<?xml version="1.0" ?>
<!-- Generated using onshape-to-robot -->
<!-- Onshape document_id: af0115e61c5582d0fb054981 -->
<robot name="project_robot">
  <!-- Link armbasemount -->
  <link name="armbasemount">
    <inertial>
      <origin xyz="1.26354e-05 0.0741953 0.0570063" rpy="0 0 0"/>
      <mass value="0.143819"/>
      <inertia ixx="0.000257205" ixy="-1.1654e-08" ixz="-4.74482e-08" iyy="0.000259368" iyz="-9.79201e-05" izz="0.00022214"/>
    </inertial>
    <!-- Part armbasemount -->
    <visual>
      <origin xyz="0 0.1156 0.06" rpy="1.5708 -0 -1.5708"/>
      <geometry>
        <mesh filename="package://robot_desc/robot/assets/armbasemount.stl"/>
      </geometry>
      <material name="armbasemount_material">
        <color rgba="0.615686 0.811765 0.929412 1.0"/>
      </material>
    </visual>
    <collision>
      <origin xyz="0 0.1156 0.06" rpy="1.5708 -0 -1.5708"/>
      <geometry>
        <mesh filename="package://robot_desc/robot/assets/armbasemount.stl"/>
      </geometry>
    </collision>
    <!-- Part dynamixelmotor_withhorn -->
    <visual>
      <origin xyz="-1.73472e-18 0.1036 0.07803" rpy="0 -0 0"/>
      <geometry>
        <mesh filename="package://robot_desc/robot/assets/dynamixelmotor_withhorn.stl"/>
      </geometry>
      <material name="dynamixelmotor_withhorn_material">
        <color rgba="0.647059 0.647059 0.647059 1.0"/>
      </material>
    </visual>
    <collision>
      <origin xyz="-1.73472e-18 0.1036 0.07803" rpy="0 -0 0"/>
      <geometry>
        <mesh filename="package://robot_desc/robot/assets/dynamixelmotor_withhorn.stl"/>
      </geometry>
    </collision>
  </link>
  <!-- Link dynamixelmotor_withhorn -->
  <link name="dynamixelmotor_withhorn">
    <inertial>
      <origin xyz="0.258669 1.8478e-05 0.0163409" rpy="0 0 0"/>
      <mass value="0.0982101"/>
      <inertia ixx="2.87078e-05" ixy="-2.9545e-08" ixz="2.09241e-05" iyy="0.000537394" iyz="1.16309e-08" izz="0.000524006"/>
    </inertial>
    <!-- Part dynamixelmotor_withhorn_2 -->
    <visual>
      <origin xyz="0.298 -5.83301e-17 0.015" rpy="3.14159 1.71531e-32 1.5708"/>
      <geometry>
        <mesh filename="package://robot_desc/robot/assets/dynamixelmotor_withhorn.stl"/>
      </geometry>
      <material name="dynamixelmotor_withhorn_2_material">
        <color rgba="0.647059 0.647059 0.647059 1.0"/>
      </material>
    </visual>
    <collision>
      <origin xyz="0.298 -5.83301e-17 0.015" rpy="3.14159 1.71531e-32 1.5708"/>
      <geometry>
        <mesh filename="package://robot_desc/robot/assets/dynamixelmotor_withhorn.stl"/>
      </geometry>
    </collision>
    <!-- Part combinedshoulder -->
    <visual>
      <origin xyz="0.169838 0.0002 0" rpy="-3.14159 -0 -2.97496e-65"/>
      <geometry>
        <mesh filename="package://robot_desc/robot/assets/combinedshoulder.stl"/>
      </geometry>
      <material name="combinedshoulder_material">
        <color rgba="0.615686 0.811765 0.929412 1.0"/>
      </material>
    </visual>
    <collision>
      <origin xyz="0.169838 0.0002 0" rpy="-3.14159 -0 -2.97496e-65"/>
      <geometry>
        <mesh filename="package://robot_desc/robot/assets/combinedshoulder.stl"/>
      </geometry>
    </collision>
  </link>
  <!-- Link hooplink -->
  <link name="hooplink">
    <inertial>
      <origin xyz="0.13582 -2.36422e-05 0.00482647" rpy="0 0 0"/>
      <mass value="0.0174"/>
      <inertia ixx="4.93554e-06" ixy="6.81023e-08" ixz="1.73507e-06" iyy="0.000152572" iyz="-1.36842e-09" izz="0.000156908"/>
    </inertial>
    <!-- Part hooplink -->
    <visual>
      <origin xyz="0.169838 0.1698 0" rpy="0 -0 2.97496e-65"/>
      <geometry>
        <mesh filename="package://robot_desc/robot/assets/hooplink.stl"/>
      </geometry>
      <material name="hooplink_material">
        <color rgba="0.615686 0.811765 0.929412 1.0"/>
      </material>
    </visual>
    <collision>
      <origin xyz="0.169838 0.1698 0" rpy="0 -0 2.97496e-65"/>
      <geometry>
        <mesh filename="package://robot_desc/robot/assets/hooplink.stl"/>
      </geometry>
    </collision>
  </link>
  <!-- Frame EEframe (dummy link + fixed joint) -->
  <link name="EEframe">
    <origin xyz="0 0 0" rpy="0 -0 0"/>
    <inertial>
      <origin xyz="0 0 0" rpy="0 0 0"/>
      <mass value="1e-9"/>
      <inertia ixx="0" ixy="0" ixz="0" iyy="0" iyz="0" izz="0"/>
    </inertial>
  </link>
  <joint name="EEframe_frame" type="fixed">
    <origin xyz="0.3 -0.0002 0.003" rpy="0 -0 2.97496e-65"/>
    <parent link="hooplink"/>
    <child link="EEframe"/>
    <axis xyz="0 0 0"/>
  </joint>
  <!-- Joint from dynamixelmotor_withhorn to hooplink -->
  <joint name="elbow" type="revolute">
    <origin xyz="0.298 3.3632e-16 -0.0055" rpy="3.14159 -1.36846e-48 -2.42861e-17"/>
    <parent link="dynamixelmotor_withhorn"/>
    <child link="hooplink"/>
    <axis xyz="0 0 1"/>
    <limit effort="10" velocity="10" lower="-2.30383" upper="2.30383"/>
  </joint>
  <!-- Joint from armbasemount to dynamixelmotor_withhorn -->
  <joint name="shoulder" type="revolute">
    <origin xyz="-1.43115e-17 0.1036 0.09853" rpy="-3.14159 1.2326e-32 1.56087"/>
    <parent link="armbasemount"/>
    <child link="dynamixelmotor_withhorn"/>
    <axis xyz="0 0 1"/>
    <limit effort="10" velocity="10" lower="-1.58072" upper="1.56087"/>
  </joint>
</robot>
